<?xml version="1.0"?>
<robot xmlns:xacro="http://www.ros.org/wiki/xacro" name="waveshare_servos">
    <xacro:arg name="prefix" default="" />

    <material name="white">
        <color rgba="1 1 1 1" />
    </material>

    <link name="base_link">
        <visual>
            <origin xyz="0 0 0.15"/>
            <geometry>
                <box size="0.1 0.1 0.3"/>
            </geometry>
            <material name="white"/>
        </visual>
    </link>

    <joint name="joint1" type="revolute">
        <axis xyz="0 0 1"/>
        <limit effort="1000.0" lower="-1.570796" upper="1.570796" velocity="0.5"/>
        <origin xyz="0 0 0.3"/>
        <parent link="base_link"/>
        <child link="link2"/>
    </joint>

    <link name="link2">
        <visual>
            <origin xyz="0 0 0.15"/>
            <geometry>
                <box size="0.1 0.1 0.3"/>
            </geometry>
            <material name="white"/>
        </visual>
    </link>

    <joint name="joint2" type="revolute">
        <axis xyz="1 0 0"/>
        <limit effort="1000.0" lower="-1.570796" upper="1.570796" velocity="0.5"/>
        <origin rpy="0 0 0" xyz="0 0 0.3"/>
        <parent link="link2"/>
        <child link="link3"/>
    </joint>

    <link name="link3">
        <visual>
            <origin xyz="0 0 0.15"/>
            <geometry>
                <box size="0.1 0.1 0.3"/>
            </geometry>
            <material name="white"/>
        </visual>
    </link>

    <joint name="joint3" type="continuous">
        <axis xyz="0 0 1"/>
        <limit effort="1000.0" lower="-3.14" upper="3.14" velocity="1.0"/>
        <origin xyz="0 0 0.3"/>
        <parent link="link3"/>
        <child link="link4"/>
    </joint>

    <link name="link4">
        <visual>
            <origin xyz="0 0 0.05"/>
            <geometry>
                <cylinder length="0.1" radius="0.1"/>
            </geometry>
            <material name="white"/>
        </visual>
    </link>

    <xacro:include filename="$(find waveshare_servos)/description/ros2_control/example.ros2_control.xacro"/>

    <xacro:example_ws_ros2_control name="example_ws_ros2_control" prefix="$(arg prefix)"/>

</robot>
